<?xml version="1.0" ?>
<robot name="tank_model" xmlns:xacro="http://www.ros.org/wiki/xacro">

    <xacro:include filename="$(find tank_model)/urdf/wheel_gazebo.xacro" />

    <xacro:macro name="wheel_joint" params="prefix lr_reflect fb_reflect">
        <joint name="${prefix}_wheel_joint" type="continuous">
            <origin xyz="${lr_reflect*0.1} ${fb_reflect*0.14} -0.05" rpy="0 0 0"/>
            <parent link="base_link"/>
            <child link="${prefix}_wheel_link"/>
            <axis xyz="0 1 0"/>
        </joint>
    </xacro:macro>

    <link name="base_link">
        <visual>
            <origin xyz=" 0 0 0" rpy="0 0 0" />
            <geometry>
                <box size="0.4 0.3 0.05" />
            </geometry>
            <material name="yellow">
                <color rgba="1 0.4 0 1"/>
            </material>
        </visual>
    </link>

    <joint name="tank_camera_joint" type="fixed">
        <origin xyz="0.2 0 0.025" rpy="0 0 0"/>
        <parent link="base_link"/>
        <child link="tank_camera_link"/>
        <axis xyz="0 1 0"/>
    </joint>

    <link name="tank_camera_link">
        <visual>
            <origin xyz=" -0.0125 0 0.015" rpy="0 0 0" />
            <geometry>
                <box size="0.025 0.1 0.03" />
            </geometry>
            <material name="green">
                <color rgba="0 1 0 1"/>
            </material>
        </visual>
    </link>

    <joint name="tank_body_joint" type="fixed">
        <origin xyz="-0.05 0 0.025" rpy="0 0 0"/>
        <parent link="base_link"/>
        <child link="tank_body_link"/>
        <axis xyz="0 1 0"/>
    </joint>

    <link name="tank_body_link">
        <visual>
            <origin xyz="0 0 0.025" rpy="0 0 0"/>
            <geometry>
                <cylinder radius="0.1" length="0.05"/>
            </geometry>
            <material name="red">
                <color rgba="1 0 0 1"/>
            </material>
        </visual>
    </link>

    <joint name="tank_laser_joint" type="fixed">
        <origin xyz="0 0 0.05" rpy="0 0 0"/>
        <parent link="tank_body_link"/>
        <child link="tank_laser_link"/>
        <axis xyz="0 1 0"/>
    </joint>

    <link name="tank_laser_link">
        <visual>
            <origin xyz="0 0 0.05" rpy="0 0 0"/>
            <geometry>
                <cylinder radius="0.05" length="0.1"/>
            </geometry>
            <material name="blue">
                <color rgba="0 0 1 1"/>
            </material>
        </visual>
    </link> 

    <xacro:wheel_joint prefix="left_front" lr_reflect="1" fb_reflect="1"/>
    <xacro:wheel prefix="left_front"/>

    <xacro:wheel_joint prefix="left" lr_reflect="1" fb_reflect="-1"/>
    <xacro:wheel prefix="left"/>

    <xacro:wheel_joint prefix="right_front" lr_reflect="-1" fb_reflect="1"/>
    <xacro:wheel prefix="right_front"/>

    <xacro:wheel_joint prefix="right" lr_reflect="-1" fb_reflect="-1"/>
    <xacro:wheel prefix="right"/>

</robot>
